Workbook
Name Slicer_Category: #N/A
Name Slicer_Month_Name: #N/A
Name Slicer_Month_Name1: #N/A
Name Slicer_Region: #N/A
Name Slicer_Region1: #N/A

Sheet Sales_Data
A1: Order_ID | B1: Order_Date | C1: Region | D1: Salesperson | E1: Product | F1: Category | G1: Quantity | H1: Unit_Price | I1: Total Sales | J1: Sales_Segment | K1: Year-Month | L1: Month Name
A2: 1001 | B2: 2024-01-09 | C2: South | D2: Priya | E2: Sofa | F2: Furniture | G2: 3 | H2: 24676 | I2: =H2*G2 -> 74028 | J2: =IF(I2>100000,"High","Normal") -> Normal | K2: {=TEXT($B$2:$B$301,"YYYY-mm")} -> 2024-01 | L2: {=TEXT($B$2:$B$301,"MMMM")} -> January | T2: BASIC LEVEL:
A3: 1002 | B3: 2024-04-21 | C3: East | D3: Karan | E3: Printer | F3: Electronics | G3: 2 | H3: 13955 | I3: =H3*G3 -> 27910 | J3: =IF(I3>100000,"High","Normal") -> Normal | K3: 2024-04 | L3: April
A4: 1003 | B4: 2024-02-23 | C4: North | D4: Priya | E4: Laptop | F4: Electronics | G4: 8 | H4: 49847 | I4: =H4*G4 -> 398776 | J4: =IF(I4>100000,"High","Normal") -> High | K4: 2024-02 | L4: February | T4: 1. Create Total Sales column (Quantity * Unit Price).
A5: 1004 | B5: 2024-04-29 | C5: South | D5: Priya | E5: Printer | F5: Electronics | G5: 1 | H5: 15273 | I5: =H5*G5 -> 15273 | J5: =IF(I5>100000,"High","Normal") -> Normal | K5: 2024-04 | L5: April | T5: Total Sales Column | U5: Quantity*Price
A6: 1005 | B6: 2024-02-19 | C6: East | D6: Karan | E6: Tablet | F6: Electronics | G6: 10 | H6: 30244 | I6: =H6*G6 -> 302440 | J6: =IF(I6>100000,"High","Normal") -> High | K6: 2024-02 | L6: February
A7: 1006 | B7: 2024-03-15 | C7: East | D7: Karan | E7: Mobile | F7: Electronics | G7: 7 | H7: 19477 | I7: =H7*G7 -> 136339 | J7: =IF(I7>100000,"High","Normal") -> High | K7: 2024-03 | L7: March | T7: 2. Find Total Revenue using SUM.
A8: 1007 | B8: 2024-06-21 | C8: West | D8: Karan | E8: Laptop | F8: Electronics | G8: 6 | H8: 52724 | I8: =H8*G8 -> 316344 | J8: =IF(I8>100000,"High","Normal") -> High | K8: 2024-06 | L8: June | T8: Total Revenue | U8: =SUM(I2:I301) -> 35813280
A9: 1008 | B9: 2024-01-28 | C9: East | D9: Riya | E9: Printer | F9: Electronics | G9: 4 | H9: 14475 | I9: =H9*G9 -> 57900 | J9: =IF(I9>100000,"High","Normal") -> Normal | K9: 2024-01 | L9: January
A10: 1009 | B10: 2024-05-26 | C10: South | D10: Sneha | E10: Chair | F10: Furniture | G10: 8 | H10: 1939 | I10: =H10*G10 -> 15512 | J10: =IF(I10>100000,"High","Normal") -> Normal | K10: 2024-05 | L10: May | T10: 3. Find Average Unit Price.
A11: 1010 | B11: 2024-06-15 | C11: South | D11: Riya | E11: Laptop | F11: Electronics | G11: 8 | H11: 50499 | I11: =H11*G11 -> 403992 | J11: =IF(I11>100000,"High","Normal") -> High | K11: 2024-06 | L11: June | T11: Average Unit Price | U11: =AVERAGE(H2:H301) -> 22158.04
A12: 1011 | B12: 2024-02-12 | C12: North | D12: Riya | E12: Desk | F12: Furniture | G12: 2 | H12: 8542 | I12: =H12*G12 -> 17084 | J12: =IF(I12>100000,"High","Normal") -> Normal | K12: 2024-02 | L12: February
A13: 1012 | B13: 2024-03-29 | C13: West | D13: Riya | E13: Laptop | F13: Electronics | G13: 8 | H13: 48393 | I13: =H13*G13 -> 387144 | J13: =IF(I13>100000,"High","Normal") -> High | K13: 2024-03 | L13: March | T13: 4. Count total number of orders.
A14: 1013 | B14: 2024-04-08 | C14: North | D14: Riya | E14: Chair | F14: Furniture | G14: 6 | H14: 564 | I14: =H14*G14 -> 3384 | J14: =IF(I14>100000,"High","Normal") -> Normal | K14: 2024-04 | L14: April | T14: Total Orders | U14: =COUNT(A2:A301) -> 300
A15: 1014 | B15: 2024-05-27 | C15: North | D15: Karan | E15: Laptop | F15: Electronics | G15: 5 | H15: 49096 | I15: =H15*G15 -> 245480 | J15: =IF(I15>100000,"High","Normal") -> High | K15: 2024-05 | L15: May
A16: 1015 | B16: 2024-06-02 | C16: East | D16: Priya | E16: Tablet | F16: Electronics | G16: 3 | H16: 28982 | I16: =H16*G16 -> 86946 | J16: =IF(I16>100000,"High","Normal") -> Normal | K16: 2024-06 | L16: June | T16: 5. Find Maximum and Minimum Unit Price.
A17: 1016 | B17: 2024-03-02 | C17: West | D17: Karan | E17: Desk | F17: Furniture | G17: 1 | H17: 9347 | I17: =H17*G17 -> 9347 | J17: =IF(I17>100000,"High","Normal") -> Normal | K17: 2024-03 | L17: March | T17: Max Unit Price | U17: =MAX(H2:H301) -> 52952
A18: 1017 | B18: 2024-05-29 | C18: East | D18: Rahul | E18: Sofa | F18: Furniture | G18: 7 | H18: 27308 | I18: =H18*G18 -> 191156 | J18: =IF(I18>100000,"High","Normal") -> High | K18: 2024-05 | L18: May | T18: Min Unit Price | U18: =MIN(H2:H301) -> 143
A19: 1018 | B19: 2024-05-10 | C19: East | D19: Priya | E19: Sofa | F19: Furniture | G19: 3 | H19: 24432 | I19: =H19*G19 -> 73296 | J19: =IF(I19>100000,"High","Normal") -> Normal | K19: 2024-05 | L19: May
A20: 1019 | B20: 2024-01-07 | C20: South | D20: Riya | E20: Mobile | F20: Electronics | G20: 1 | H20: 18393 | I20: =H20*G20 -> 18393 | J20: =IF(I20>100000,"High","Normal") -> Normal | K20: 2024-01 | L20: January | T20: 6. Apply Filter to show only Electronics category.
A21: 1020 | B21: 2024-01-18 | C21: East | D21: Rahul | E21: Mobile | F21: Electronics | G21: 1 | H21: 18574 | I21: =H21*G21 -> 18574 | J21: =IF(I21>100000,"High","Normal") -> Normal | K21: 2024-01 | L21: January
A22: 1021 | B22: 2024-04-06 | C22: South | D22: Sneha | E22: Desk | F22: Furniture | G22: 9 | H22: 7786 | I22: =H22*G22 -> 70074 | J22: =IF(I22>100000,"High","Normal") -> Normal | K22: 2024-04 | L22: April | T22: INTERMEDIATE LEVEL:
A23: 1022 | B23: 2024-03-17 | C23: North | D23: Sneha | E23: Sofa | F23: Furniture | G23: 7 | H23: 24826 | I23: =H23*G23 -> 173782 | J23: =IF(I23>100000,"High","Normal") -> High | K23: 2024-03 | L23: March
A24: 1023 | B24: 2024-05-29 | C24: West | D24: Priya | E24: Sofa | F24: Furniture | G24: 9 | H24: 27718 | I24: =H24*G24 -> 249462 | J24: =IF(I24>100000,"High","Normal") -> High | K24: 2024-05 | L24: May | T24: 7. Create IF column: High Sale if Total Sales > 100000 else Normal.
A25: 1024 | B25: 2024-04-24 | C25: East | D25: Amit | E25: Laptop | F25: Electronics | G25: 10 | H25: 52258 | I25: =H25*G25 -> 522580 | J25: =IF(I25>100000,"High","Normal") -> High | K25: 2024-04 | L25: April
A26: 1025 | B26: 2024-06-25 | C26: North | D26: Rahul | E26: Laptop | F26: Electronics | G26: 2 | H26: 52428 | I26: =H26*G26 -> 104856 | J26: =IF(I26>100000,"High","Normal") -> High | K26: 2024-06 | L26: June | T26: 8. Calculate total sales by Regions.
A27: 1026 | B27: 2024-01-15 | C27: North | D27: Priya | E27: Mobile | F27: Electronics | G27: 5 | H27: 22355 | I27: =H27*G27 -> 111775 | J27: =IF(I27>100000,"High","Normal") -> High | K27: 2024-01 | L27: January
A28: 1027 | B28: 2024-02-05 | C28: North | D28: Priya | E28: Tablet | F28: Electronics | G28: 8 | H28: 28350 | I28: =H28*G28 -> 226800 | J28: =IF(I28>100000,"High","Normal") -> High | K28: 2024-02 | L28: February | T28: {=_xlfn.UNIQUE(C2:C301)} -> South | U28: {=SUMIF($C$2:$C$301,$T$28:$T$31,$I$2:$I$301)} -> 8790984
A29: 1028 | B29: 2024-02-23 | C29: East | D29: Rahul | E29: Desk | F29: Furniture | G29: 9 | H29: 9306 | I29: =H29*G29 -> 83754 | J29: =IF(I29>100000,"High","Normal") -> Normal | K29: 2024-02 | L29: February | T29: East | U29: 10044810
A30: 1029 | B30: 2024-06-13 | C30: South | D30: Riya | E30: Printer | F30: Electronics | G30: 10 | H30: 13512 | I30: =H30*G30 -> 135120 | J30: =IF(I30>100000,"High","Normal") -> High | K30: 2024-06 | L30: June | T30: North | U30: 8259590
A31: 1030 | B31: 2024-04-20 | C31: East | D31: Karan | E31: Printer | F31: Electronics | G31: 9 | H31: 14098 | I31: =H31*G31 -> 126882 | J31: =IF(I31>100000,"High","Normal") -> High | K31: 2024-04 | L31: April | T31: West | U31: 8717896
A32: 1031 | B32: 2024-01-09 | C32: West | D32: Priya | E32: Desk | F32: Furniture | G32: 5 | H32: 6938 | I32: =H32*G32 -> 34690 | J32: =IF(I32>100000,"High","Normal") -> Normal | K32: 2024-01 | L32: January
A33: 1032 | B33: 2024-02-24 | C33: South | D33: Priya | E33: Desk | F33: Furniture | G33: 2 | H33: 8112 | I33: =H33*G33 -> 16224 | J33: =IF(I33>100000,"High","Normal") -> Normal | K33: 2024-02 | L33: February | T33: 9. Calculate total quantity sold for each Category.
A34: 1033 | B34: 2024-01-01 | C34: South | D34: Karan | E34: Laptop | F34: Electronics | G34: 8 | H34: 49994 | I34: =H34*G34 -> 399952 | J34: =IF(I34>100000,"High","Normal") -> High | K34: 2024-01 | L34: January | T34: {=_xlfn.UNIQUE(F2:F301)} -> Furniture | U34: {=SUMIF($F$2:$F$301,$T$34:$T$35,$I$2:$I$301)} -> 7916644
A35: 1034 | B35: 2024-03-04 | C35: East | D35: Karan | E35: Laptop | F35: Electronics | G35: 3 | H35: 50084 | I35: =H35*G35 -> 150252 | J35: =IF(I35>100000,"High","Normal") -> High | K35: 2024-03 | L35: March | T35: Electronics | U35: 27896636
A36: 1035 | B36: 2024-02-18 | C36: West | D36: Sneha | E36: Mobile | F36: Electronics | G36: 8 | H36: 18531 | I36: =H36*G36 -> 148248 | J36: =IF(I36>100000,"High","Normal") -> High | K36: 2024-02 | L36: February
A37: 1036 | B37: 2024-03-10 | C37: West | D37: Karan | E37: Chair | F37: Furniture | G37: 9 | H37: 1820 | I37: =H37*G37 -> 16380 | J37: =IF(I37>100000,"High","Normal") -> Normal | K37: 2024-03 | L37: March | T37: 10. Find total sales by Salesperson .
A38: 1037 | B38: 2024-04-07 | C38: South | D38: Karan | E38: Printer | F38: Electronics | G38: 6 | H38: 17688 | I38: =H38*G38 -> 106128 | J38: =IF(I38>100000,"High","Normal") -> High | K38: 2024-04 | L38: April | T38: {=_xlfn.UNIQUE($D$2:$D$301)} -> Priya | U38: {=SUMIF($D$2:$D$301,$T$38:$T$43,$I$2:$I$301)} -> 7179924
A39: 1038 | B39: 2024-06-10 | C39: North | D39: Karan | E39: Tablet | F39: Electronics | G39: 10 | H39: 30984 | I39: =H39*G39 -> 309840 | J39: =IF(I39>100000,"High","Normal") -> High | K39: 2024-06 | L39: June | T39: Karan | U39: 6730035
A40: 1039 | B40: 2024-04-06 | C40: East | D40: Sneha | E40: Printer | F40: Electronics | G40: 5 | H40: 14256 | I40: =H40*G40 -> 71280 | J40: =IF(I40>100000,"High","Normal") -> Normal | K40: 2024-04 | L40: April | T40: Riya | U40: 3745303
...

Sheet Practice_Questions
A1: BASIC LEVEL:
A2: 1. Create Total Sales column (Quantity * Unit Price).
A3: 2. Find Total Revenue using SUM.
A4: 3. Find Average Unit Price.
A5: 4. Count total number of orders.
A6: 5. Find Maximum and Minimum Unit Price.
A7: 6. Apply Filter to show only Electronics category.
A9: INTERMEDIATE LEVEL:
A10: 7. Create IF column: High Sale if Total Sales > 100000 else Normal.
A11: 8. Calculate total sales by Region using SUMIF.
A12: 9. Calculate total quantity sold for each Category.
A13: 10. Find total sales by Salesperson using SUMIFS.
... A35: 30. Create a complete Sales Dashboard.

Sheet 23. Pivot and slicer
C13: Salesperson | D13: Total_Sales | J13: Month | K13: Total_Sales
C14: Amit | D14: 5944874 | J14: January | K14: 5952692
C15: Karan | D15: 6730035 | J15: February | K15: 5248903
C16: Priya | D16: 7179924 | J16: March | K16: 5977072
C17: Rahul | D17: 6319916 | J17: April | K17: 5774225
C18: Riya | D18: 3745303 | J18: May | K18: 5697725
C19: Sneha | D19: 5893228 | J19: June | K19: 7162663
C22: Category | D22: Total_Sales | J22: Product | K22: Total_Sales
C23: Electronics | D23: 27896636 | J23: Chair | K23: 713888
C24: Furniture | D24: 7916644 | J24: Desk | K24: 1367437
J25: Laptop | K25: 13633591
J26: Mobile | K26: 4036049
C27: Region | D27: Total_Sales | J27: Printer | K27: 3474922
C28: East | D28: 10044810 | J28: Sofa | K28: 5835319
C29: North | D29: 8259590 | J29: Tablet | K29: 6752074
C30: South | D30: 8790984
C31: West | D31: 8717896

Sheet q.24 to q.29
B2: 24. Use VLOOKUP/XLOOKUP to fetch price from separate lookup table.
B3: Xlookup
B5: Product | C5: Price
B6: {=_xlfn.UNIQUE(Sales_Data!$E$2:$E$301)} -> Sofa | C6: =_xlfn.XLOOKUP('q.24 to q.29'!B6,Sales_Data!$E$2:$E$301,Sales_Data!$H$2:$H$301) -> 24676
B7: Printer | C7: =_xlfn.XLOOKUP('q.24 to q.29'!B7,Sales_Data!$E$2:$E$301,Sales_Data!$H$2:$H$301) -> 13955
B8: Laptop | C8: =_xlfn.XLOOKUP('q.24 to q.29'!B8,Sales_Data!$E$2:$E$301,Sales_Data!$H$2:$H$301) -> 49847
B9: Tablet | C9: =_xlfn.XLOOKUP('q.24 to q.29'!B9,Sales_Data!$E$2:$E$301,Sales_Data!$H$2:$H$301) -> 30244
B10: Mobile | C10: =_xlfn.XLOOKUP('q.24 to q.29'!B10,Sales_Data!$E$2:$E$301,Sales_Data!$H$2:$H$301) -> 19477
B11: Chair | C11: =_xlfn.XLOOKUP('q.24 to q.29'!B11,Sales_Data!$E$2:$E$301,Sales_Data!$H$2:$H$301) -> 1939
B12: Desk | C12: =_xlfn.XLOOKUP('q.24 to q.29'!B12,Sales_Data!$E$2:$E$301,Sales_Data!$H$2:$H$301) -> 8542
B14: 25. Use INDEX + MATCH for dynamic lookup.
B15: Index and Match
B17: Product | C17: Price
B18: {=_xlfn.UNIQUE(Sales_Data!$E$2:$E$301)} -> Sofa | C18: =INDEX(Sales_Data!$A$2:$L$301,MATCH('q.24 to q.29'!B18,Sales_Data!$E$2:$E$301,0),8) -> 24676
B19: Printer | C19: =INDEX(Sales_Data!$A$2:$L$301,MATCH('q.24 to q.29'!B19,Sales_Data!$E$2:$E$301,0),8) -> 13955
B20: Laptop | C20: =INDEX(Sales_Data!$A$2:$L$301,MATCH('q.24 to q.29'!B20,Sales_Data!$E$2:$E$301,0),8) -> 49847
B21: Tablet | C21: =INDEX(Sales_Data!$A$2:$L$301,MATCH('q.24 to q.29'!B21,Sales_Data!$E$2:$E$301,0),8) -> 30244
B22: Mobile | C22: =INDEX(Sales_Data!$A$2:$L$301,MATCH('q.24 to q.29'!B22,Sales_Data!$E$2:$E$301,0),8) -> 19477
B23: Chair | C23: =INDEX(Sales_Data!$A$2:$L$301,MATCH('q.24 to q.29'!B23,Sales_Data!$E$2:$E$301,0),8) -> 1939
B24: Desk | C24: =INDEX(Sales_Data!$A$2:$L$301,MATCH('q.24 to q.29'!B24,Sales_Data!$E$2:$E$301,0),8) -> 8542
B27: 26. Create Data Validation dropdown for Region.
B29: Product Dropdown
B30: Printer | C30: =_xlfn.XLOOKUP('q.24 to q.29'!B30,Sales_Data!$E$2:$E$301,Sales_Data!$H$2:$H$301) -> 13955
B32: 27. Use IFERROR with lookup formula.
B33: Xlookup with Iferror
B35: Product | C35: Price
B36: {=_xlfn.UNIQUE(Sales_Data!$E$2:$E$301)} -> Sofa | C36: =IFERROR(_xlfn.XLOOKUP(B36,Sales_Data!$E$2:$E$301,Sales_Data!$H$2:$H$301),"NA") -> 24676
B37: Printer | C37: =IFERROR(_xlfn.XLOOKUP(B37,Sales_Data!$E$2:$E$301,Sales_Data!$H$2:$H$301),"NA") -> 13955
B38: Laptop | C38: =IFERROR(_xlfn.XLOOKUP(B38,Sales_Data!$E$2:$E$301,Sales_Data!$H$2:$H$301),"NA") -> 49847
B39: Tablet | C39: =IFERROR(_xlfn.XLOOKUP(B39,Sales_Data!$E$2:$E$301,Sales_Data!$H$2:$H$301),"NA") -> 30244
B40: Mobile | C40: =IFERROR(_xlfn.XLOOKUP(B40,Sales_Data!$E$2:$E$301,Sales_Data!$H$2:$H$301),"NA") -> 19477
B41: Chair | C41: =IFERROR(_xlfn.XLOOKUP(B41,Sales_Data!$E$2:$E$301,Sales_Data!$H$2:$H$301),"NA") -> 1939
B42: Desk | C42: =IFERROR(_xlfn.XLOOKUP(B42,Sales_Data!$E$2:$E$301,Sales_Data!$H$2:$H$301),"NA") -> 8542
B43: PC | C43: =IFERROR(_xlfn.XLOOKUP(B43,Sales_Data!$E$2:$E$301,Sales_Data!$H$2:$H$301),"NA") -> NA
B46: 28. Rank Salesperson based on total sales.
B48: Salespersons | C48: Total Sales | D48: Rank
B49: {=_xlfn.UNIQUE(Sales_Data!$D$2:$D$301)} -> Priya | C49: =SUMIF(Sales_Data!$D$2:$D$301,'q.24 to q.29'!B49,Sales_Data!$I$2:$I$301) -> 7179924 | D49: =_xlfn.RANK.EQ(C49,$C$49:$C$54,0) -> 1
B50: Karan | C50: =SUMIF(Sales_Data!$D$2:$D$301,'q.24 to q.29'!B50,Sales_Data!$I$2:$I$301) -> 6730035 | D50: =_xlfn.RANK.EQ(C50,$C$49:$C$54,0) -> 2
B51: Riya | C51: =SUMIF(Sales_Data!$D$2:$D$301,'q.24 to q.29'!B51,Sales_Data!$I$2:$I$301) -> 3745303 | D51: =_xlfn.RANK.EQ(C51,$C$49:$C$54,0) -> 6
B52: Sneha | C52: =SUMIF(Sales_Data!$D$2:$D$301,'q.24 to q.29'!B52,Sales_Data!$I$2:$I$301) -> 5893228 | D52: =_xlfn.RANK.EQ(C52,$C$49:$C$54,0) -> 5
...

Sheet Pivoting
B2: Row Labels | C2: Sum of Total Sales | E2: Row Labels | F2: Sum of Total Sales
B3: East | C3: 10044810 | E3: January | F3: 5952692
B4: North | C4: 8259590 | E4: February | F4: 5248903
B5: South | C5: 8790984 | E5: March | F5: 5977072
B6: West | C6: 8717896 | E6: April | F6: 5774225
B7: Grand Total | C7: 35813280 | E7: May | F7: 5697725
E8: June | F8: 7162663
B9: Row Labels | C9: Sum of Total Sales | E9: Grand Total | F9: 35813280
B10: Chair | C10: 713888
B11: Desk | C11: 1367437 | E11: Row Labels | F11: Sum of Quantity
B12: Laptop | C12: 13633591 | E12: Chair | F12: 280
B13: Mobile | C13: 4036049 | E13: Desk | F13: 176
B14: Printer | C14: 3474922 | E14: Laptop | F14: 271
B15: Sofa | C15: 5835319 | E15: Mobile | F15: 201
B16: Tablet | C16: 6752074 | E16: Printer | F16: 232
B17: Grand Total | C17: 35813280 | E17: Sofa | F17: 229
E18: Tablet | F18: 221
B19: Row Labels | C19: Average of Unit_Price | E19: Grand Total | F19: 1610
B20: Chair | C20: 2343.3617
B21: Desk | C21: 7658.25 | E21: Sum of Total Sales | F21: Average of Unit_Price
B22: Laptop | C22: 50413.562 | E22: 35813280 | F22: 22158.04
B23: Mobile | C23: 19979.225
B24: Printer | C24: 15007.93 | E24: Count of Order_ID | F24: Sum of Quantity
B25: Sofa | C25: 25311.814 | E25: 300 | F25: 1610
B26: Tablet | C26: 30437.395
B27: Grand Total | C27: 22158.04
H48: Row Labels | I48: Sum of Total Sales
H49: Electronics | I49: 27896636
H50: Furniture | I50: 7916644
H51: Grand Total | I51: 35813280

Sheet Dashboard
